[0m14:26:36.926687 [debug] [MainThread]: Sending event: {'category': 'dbt', 'action': 'invocation', 'label': 'start', 'context': [<snowplow_tracker.self_describing_json.SelfDescribingJson object at 0x000002615ADB9E80>, <snowplow_tracker.self_describing_json.SelfDescribingJson object at 0x000002615D74BED0>, <snowplow_tracker.self_describing_json.SelfDescribingJson object at 0x000002615D74BC50>]}


============================== 14:26:36.931109 | 69cccc32-8f29-4d69-9649-8b1a6041843f ==============================
[0m14:26:36.931109 [info ] [MainThread]: Running with dbt=1.7.9
[0m14:26:36.931901 [debug] [MainThread]: running dbt with arguments {'printer_width': '80', 'indirect_selection': 'eager', 'log_cache_events': 'False', 'write_json': 'True', 'partial_parse': 'True', 'cache_selected_only': 'False', 'profiles_dir': 'C:\\Users\\alixo\\.dbt', 'debug': 'False', 'warn_error': 'None', 'log_path': 'C:\\Users\\alixo\\desktop\\ETL\\logs', 'fail_fast': 'False', 'version_check': 'True', 'use_colors': 'True', 'use_experimental_parser': 'False', 'no_print': 'None', 'quiet': 'False', 'warn_error_options': 'WarnErrorOptions(include=[], exclude=[])', 'invocation_command': 'dbt run', 'log_format': 'default', 'introspect': 'True', 'target_path': 'None', 'static_parser': 'True', 'send_anonymous_usage_stats': 'True'}
[0m14:26:37.024602 [error] [MainThread]: Encountered an error:
Runtime Error
  Credentials in profile "ETL", target "dev" invalid: ['schema'] is not valid under any of the given schemas
[0m14:26:37.026207 [debug] [MainThread]: Command `dbt run` failed at 14:26:37.026066 after 0.21 seconds
[0m14:26:37.026545 [debug] [MainThread]: Sending event: {'category': 'dbt', 'action': 'invocation', 'label': 'end', 'context': [<snowplow_tracker.self_describing_json.SelfDescribingJson object at 0x000002615DA21E00>, <snowplow_tracker.self_describing_json.SelfDescribingJson object at 0x000002615DDF5EB0>, <snowplow_tracker.self_describing_json.SelfDescribingJson object at 0x000002615DA0EF10>]}
[0m14:26:37.026842 [debug] [MainThread]: Flushing usage events
[0m14:27:20.186383 [debug] [MainThread]: Sending event: {'category': 'dbt', 'action': 'invocation', 'label': 'start', 'context': [<snowplow_tracker.self_describing_json.SelfDescribingJson object at 0x000001A788E19E80>, <snowplow_tracker.self_describing_json.SelfDescribingJson object at 0x000001A78B7BBED0>, <snowplow_tracker.self_describing_json.SelfDescribingJson object at 0x000001A78B7BBC50>]}


============================== 14:27:20.190910 | 53bc7a97-d096-4d38-9a1b-10c7b8567c3f ==============================
[0m14:27:20.190910 [info ] [MainThread]: Running with dbt=1.7.9
[0m14:27:20.191680 [debug] [MainThread]: running dbt with arguments {'printer_width': '80', 'indirect_selection': 'eager', 'write_json': 'True', 'log_cache_events': 'False', 'partial_parse': 'True', 'cache_selected_only': 'False', 'profiles_dir': 'C:\\Users\\alixo\\.dbt', 'debug': 'False', 'warn_error': 'None', 'log_path': 'C:\\Users\\alixo\\desktop\\ETL\\logs', 'fail_fast': 'False', 'version_check': 'True', 'use_colors': 'True', 'use_experimental_parser': 'False', 'no_print': 'None', 'quiet': 'False', 'log_format': 'default', 'introspect': 'True', 'warn_error_options': 'WarnErrorOptions(include=[], exclude=[])', 'static_parser': 'True', 'target_path': 'None', 'invocation_command': 'dbt run --select stg_customers', 'send_anonymous_usage_stats': 'True'}
[0m14:27:20.258483 [error] [MainThread]: Encountered an error:
Runtime Error
  Credentials in profile "ETL", target "dev" invalid: ['schema'] is not valid under any of the given schemas
[0m14:27:20.259998 [debug] [MainThread]: Command `dbt run` failed at 14:27:20.259799 after 0.23 seconds
[0m14:27:20.260314 [debug] [MainThread]: Sending event: {'category': 'dbt', 'action': 'invocation', 'label': 'end', 'context': [<snowplow_tracker.self_describing_json.SelfDescribingJson object at 0x000001A78BA11E00>, <snowplow_tracker.self_describing_json.SelfDescribingJson object at 0x000001A78BDE5EB0>, <snowplow_tracker.self_describing_json.SelfDescribingJson object at 0x000001A78B9FEF10>]}
[0m14:27:20.260662 [debug] [MainThread]: Flushing usage events
[0m14:27:32.737505 [debug] [MainThread]: Sending event: {'category': 'dbt', 'action': 'invocation', 'label': 'start', 'context': [<snowplow_tracker.self_describing_json.SelfDescribingJson object at 0x000001F56FCC9E80>, <snowplow_tracker.self_describing_json.SelfDescribingJson object at 0x000001F57265BED0>, <snowplow_tracker.self_describing_json.SelfDescribingJson object at 0x000001F57265BC50>]}


============================== 14:27:32.741564 | e3b05f35-f536-460f-b9cc-82b6fe0099e3 ==============================
[0m14:27:32.741564 [info ] [MainThread]: Running with dbt=1.7.9
[0m14:27:32.742167 [debug] [MainThread]: running dbt with arguments {'printer_width': '80', 'indirect_selection': 'eager', 'log_cache_events': 'False', 'write_json': 'True', 'partial_parse': 'True', 'cache_selected_only': 'False', 'warn_error': 'None', 'fail_fast': 'False', 'debug': 'False', 'log_path': 'C:\\Users\\alixo\\desktop\\ETL\\logs', 'profiles_dir': 'C:\\Users\\alixo\\.dbt', 'version_check': 'True', 'use_colors': 'True', 'use_experimental_parser': 'False', 'no_print': 'None', 'quiet': 'False', 'warn_error_options': 'WarnErrorOptions(include=[], exclude=[])', 'introspect': 'True', 'static_parser': 'True', 'invocation_command': 'dbt run --select models/staging/*', 'target_path': 'None', 'log_format': 'default', 'send_anonymous_usage_stats': 'True'}
[0m14:27:32.806876 [error] [MainThread]: Encountered an error:
Runtime Error
  Credentials in profile "ETL", target "dev" invalid: ['schema'] is not valid under any of the given schemas
[0m14:27:32.808437 [debug] [MainThread]: Command `dbt run` failed at 14:27:32.808292 after 0.17 seconds
[0m14:27:32.808771 [debug] [MainThread]: Sending event: {'category': 'dbt', 'action': 'invocation', 'label': 'end', 'context': [<snowplow_tracker.self_describing_json.SelfDescribingJson object at 0x000001F5728C1E00>, <snowplow_tracker.self_describing_json.SelfDescribingJson object at 0x000001F572C95EB0>, <snowplow_tracker.self_describing_json.SelfDescribingJson object at 0x000001F5728AEF10>]}
[0m14:27:32.809247 [debug] [MainThread]: Flushing usage events
[0m14:29:07.687591 [debug] [MainThread]: Sending event: {'category': 'dbt', 'action': 'invocation', 'label': 'start', 'context': [<snowplow_tracker.self_describing_json.SelfDescribingJson object at 0x0000013268AC9E80>, <snowplow_tracker.self_describing_json.SelfDescribingJson object at 0x000001326B45BED0>, <snowplow_tracker.self_describing_json.SelfDescribingJson object at 0x000001326B45BC50>]}


============================== 14:29:07.691671 | ad4a0f0e-a02b-4135-a6aa-59803d79e712 ==============================
[0m14:29:07.691671 [info ] [MainThread]: Running with dbt=1.7.9
[0m14:29:07.692285 [debug] [MainThread]: running dbt with arguments {'printer_width': '80', 'indirect_selection': 'eager', 'write_json': 'True', 'log_cache_events': 'False', 'partial_parse': 'True', 'cache_selected_only': 'False', 'profiles_dir': 'C:\\Users\\alixo\\.dbt', 'fail_fast': 'False', 'version_check': 'True', 'log_path': 'C:\\Users\\alixo\\desktop\\ETL\\logs', 'debug': 'False', 'warn_error': 'None', 'use_colors': 'True', 'use_experimental_parser': 'False', 'no_print': 'None', 'quiet': 'False', 'log_format': 'default', 'invocation_command': 'dbt run --select models/staging/*', 'static_parser': 'True', 'warn_error_options': 'WarnErrorOptions(include=[], exclude=[])', 'target_path': 'None', 'introspect': 'True', 'send_anonymous_usage_stats': 'True'}
[0m14:29:07.758135 [error] [MainThread]: Encountered an error:
Runtime Error
  Credentials in profile "ETL", target "dev" invalid: ['schema'] is not valid under any of the given schemas
[0m14:29:07.759519 [debug] [MainThread]: Command `dbt run` failed at 14:29:07.759380 after 0.19 seconds
[0m14:29:07.759860 [debug] [MainThread]: Sending event: {'category': 'dbt', 'action': 'invocation', 'label': 'end', 'context': [<snowplow_tracker.self_describing_json.SelfDescribingJson object at 0x000001326B651E00>, <snowplow_tracker.self_describing_json.SelfDescribingJson object at 0x000001326BA25EB0>, <snowplow_tracker.self_describing_json.SelfDescribingJson object at 0x000001326B63EF10>]}
[0m14:29:07.760208 [debug] [MainThread]: Flushing usage events
[0m15:31:53.961521 [debug] [MainThread]: Sending event: {'category': 'dbt', 'action': 'invocation', 'label': 'start', 'context': [<snowplow_tracker.self_describing_json.SelfDescribingJson object at 0x0000023CC7CD9E80>, <snowplow_tracker.self_describing_json.SelfDescribingJson object at 0x0000023CCA67BED0>, <snowplow_tracker.self_describing_json.SelfDescribingJson object at 0x0000023CCA67BC50>]}


============================== 15:31:53.966107 | 015db310-0ad3-4299-97bd-f801f95c3be4 ==============================
[0m15:31:53.966107 [info ] [MainThread]: Running with dbt=1.7.9
[0m15:31:53.966739 [debug] [MainThread]: running dbt with arguments {'printer_width': '80', 'indirect_selection': 'eager', 'write_json': 'True', 'log_cache_events': 'False', 'partial_parse': 'True', 'cache_selected_only': 'False', 'profiles_dir': 'C:\\Users\\alixo\\.dbt', 'version_check': 'True', 'fail_fast': 'False', 'log_path': 'C:\\Users\\alixo\\desktop\\ETL\\logs', 'debug': 'False', 'warn_error': 'None', 'use_colors': 'True', 'use_experimental_parser': 'False', 'no_print': 'None', 'quiet': 'False', 'log_format': 'default', 'static_parser': 'True', 'invocation_command': 'dbt run', 'introspect': 'True', 'target_path': 'None', 'warn_error_options': 'WarnErrorOptions(include=[], exclude=[])', 'send_anonymous_usage_stats': 'True'}
[0m15:31:54.033158 [error] [MainThread]: Encountered an error:
Runtime Error
  Credentials in profile "ETL", target "dev" invalid: ['schema'] is not valid under any of the given schemas
[0m15:31:54.034720 [debug] [MainThread]: Command `dbt run` failed at 15:31:54.034487 after 0.29 seconds
[0m15:31:54.035124 [debug] [MainThread]: Sending event: {'category': 'dbt', 'action': 'invocation', 'label': 'end', 'context': [<snowplow_tracker.self_describing_json.SelfDescribingJson object at 0x0000023CCA861E00>, <snowplow_tracker.self_describing_json.SelfDescribingJson object at 0x0000023CCAC65EB0>, <snowplow_tracker.self_describing_json.SelfDescribingJson object at 0x0000023CCA84EF10>]}
[0m15:31:54.035392 [debug] [MainThread]: Flushing usage events
[0m10:53:24.676199 [debug] [MainThread]: Sending event: {'category': 'dbt', 'action': 'invocation', 'label': 'start', 'context': [<snowplow_tracker.self_describing_json.SelfDescribingJson object at 0x000002A8EF079E80>, <snowplow_tracker.self_describing_json.SelfDescribingJson object at 0x000002A8F1A0BED0>, <snowplow_tracker.self_describing_json.SelfDescribingJson object at 0x000002A8F1A0BC50>]}


============================== 10:53:24.688544 | 04ef91c5-9a13-4f1c-8d53-8ebfd438c45a ==============================
[0m10:53:24.688544 [info ] [MainThread]: Running with dbt=1.7.9
[0m10:53:24.689817 [debug] [MainThread]: running dbt with arguments {'printer_width': '80', 'indirect_selection': 'eager', 'log_cache_events': 'False', 'write_json': 'True', 'partial_parse': 'True', 'cache_selected_only': 'False', 'profiles_dir': 'C:\\Users\\alixo\\.dbt', 'debug': 'False', 'version_check': 'True', 'log_path': 'C:\\Users\\alixo\\desktop\\ETL\\logs', 'warn_error': 'None', 'fail_fast': 'False', 'use_colors': 'True', 'use_experimental_parser': 'False', 'no_print': 'None', 'quiet': 'False', 'warn_error_options': 'WarnErrorOptions(include=[], exclude=[])', 'static_parser': 'True', 'log_format': 'default', 'introspect': 'True', 'target_path': 'None', 'invocation_command': 'dbt run', 'send_anonymous_usage_stats': 'True'}
[0m10:53:24.816412 [error] [MainThread]: Encountered an error:
Runtime Error
  Credentials in profile "ETL", target "dev" invalid: ['schema'] is not valid under any of the given schemas
[0m10:53:24.818541 [debug] [MainThread]: Command `dbt run` failed at 10:53:24.818144 after 0.34 seconds
[0m10:53:24.819041 [debug] [MainThread]: Sending event: {'category': 'dbt', 'action': 'invocation', 'label': 'end', 'context': [<snowplow_tracker.self_describing_json.SelfDescribingJson object at 0x000002A8F1C01E00>, <snowplow_tracker.self_describing_json.SelfDescribingJson object at 0x000002A8F1FD5EB0>, <snowplow_tracker.self_describing_json.SelfDescribingJson object at 0x000002A8F1BEEF10>]}
[0m10:53:24.819558 [debug] [MainThread]: Flushing usage events
